<?xml version="1.0" ?>
<sdf version="1.6">
  <world name="simple_pendulum_world">
    <physics type="ode">
      <max_step_size>0.001</max_step_size>
      <real_time_factor>1.0</real_time_factor>
      <real_time_update_rate>1000</real_time_update_rate>
      <ode>
        <solver>
          <type>quick</type>
          <iters>50</iters>
          <sor>1.3</sor>
          <friction_model>cone_model</friction_model>
        </solver>
        <constraints>
          <cfm>0</cfm>
          <erp>0.2</erp>
        </constraints>
        <contact>
          <ode>
            <soft_cfm>0</soft_cfm>
            <soft_erp>0.2</soft_erp>
            <kp>1e+08</kp>
            <kd>1</kd>
          </ode>
        </contact>
      </ode>
    </physics>
    <scene>
      <ambient>0.4 0.4 0.4 1</ambient>
      <background>0.7 0.7 0.7 1</background>
      <shadows>true</shadows>
    </scene>
    <include>
      <uri>model://sun</uri>
    </include>

    <model name="base_link">
      <pose>0 0 1 0 0 0</pose>
      <link name="base_link_fixed">
        <inertial>
          <mass>0.1</mass>
          <inertia>
            <ixx>0.0001</ixx> <iyy>0.0001</iyy> <izz>0.0001</izz>
          </inertia>
        </inertial>
        <visual>
          <geometry>
            <box>
              <size>0.05 0.05 0.05</size>
            </box>
          </geometry>
          <material>
            <ambient>0.1 0.1 0.1 1</ambient>
            <diffuse>0.1 0.1 0.1 1</diffuse>
            <specular>0.01 0.01 0.01 1</specular>
            <emissive>0 0 0 0</emissive>
          </material>
        </visual>
        <collision>
          <geometry>
            <box>
              <size>0.05 0.05 0.05</size>
            </box>
          </geometry>
        </collision>
      </link>

      <joint name="pendulum_joint" type="revolute">
        <parent>base_link_fixed</parent>
        <child>pendulum_link</child>
        <pose>0 0 -0.1 0 0 0</pose>
        <axis>
          <xyz>0 1 0</xyz>
        </axis>
      </joint>

      <link name="pendulum_link">
        <inertial>
          <mass>1.0</mass>
          <inertia>
            <ixx>0.083</ixx> <iyy>0.083</iyy> <izz>0.001</izz>
          </inertia>
        </inertial>
        <visual>
          <geometry>
            <box>
              <size>0.02 0.02 0.2</size>
            </box>
          </geometry>
          <material>
            <ambient>0 0 1 1</ambient>
            <diffuse>0 0 1 1</diffuse>
            <specular>0 0 1 1</specular>
            <emissive>0 0 0 0</emissive>
          </material>
        </visual>
        <collision>
          <geometry>
            <box>
              <size>0.02 0.02 0.2</size>
            </box>
          </geometry>
        </collision>
      </link>
    </model>

  </world>
</sdf>
