<?xml version="1.0"?>
<robot name="simple_arm">

  <!-- Base Link -->
  <link name="base_link">
    <visual>
      <geometry>
        <box size="0.1 0.1 0.1" />
      </geometry>
      <material name="blue">
        <color rgba="0 0 1 1" />
      </material>
    </visual>
    <collision>
      <geometry>
        <box size="0.1 0.1 0.1" />
      </geometry>
    </collision>
    <inertial>
      <mass value="0.1" />
      <inertia ixx="0.0001" ixy="0" ixz="0" iyy="0.0001" iyz="0" izz="0.0001" />
    </inertial>
  </link>

  <!-- Joint between base_link and link1 -->
  <joint name="base_to_link1_joint" type="revolute">
    <parent link="base_link" />
    <child link="link1" />
    <origin xyz="0 0 0.05" rpy="0 0 0" />
    <axis xyz="0 0 1" />
    <limit lower="-1.57" upper="1.57" effort="10" velocity="10" />
  </joint>

  <!-- Link 1 -->
  <link name="link1">
    <visual>
      <geometry>
        <cylinder length="0.2" radius="0.02" />
      </geometry>
      <origin xyz="0 0 0.1" rpy="0 0 0" />
      <material name="red">
        <color rgba="1 0 0 1" />
      </material>
    </visual>
    <collision>
      <geometry>
        <cylinder length="0.2" radius="0.02" />
      </geometry>
      <origin xyz="0 0 0.1" rpy="0 0 0" />
    </collision>
    <inertial>
      <mass value="0.05" />
      <inertia ixx="0.0001" ixy="0" ixz="0" iyy="0.0001" iyz="0" izz="0.0001" />
    </inertial>
  </link>

  <material name="blue" />
  <material name="red" />

</robot>
